<?xml version="1.0"?>
<robot name="simple_myo_robot">
  <link name ="world"/>
  <link name="base_link">
    <visual>
      <geometry>
        <cylinder length="0.05" radius="0.1"/>
      </geometry>
      <material name="silver">
        <color rgba="0.75 0.75 0.75 1"/>
      </material>
      <origin rpy="0 0 0" xyz="0 0 0"/>
    </visual>
  </link>
  <joint name="fixed" type="fixed">
    <parent link ="world"/>
    <child link ="base_link"/>
  </joint>
  <link name="upper_arm">
    <visual>
      <geometry>
        <cylinder length="0.5" radius="0.05"/>
      </geometry>
      <material name="silver">
        <color rgba="0.75 0.75 0.75 1"/>
      </material>
      <origin rpy="0 0 0" xyz="0 0 0.25"/>
    </visual>
  </link>
  <joint name="shoulder" type="fixed">
    <parent link ="base_link"/>
    <child link ="upper_arm"/>
  </joint>
  <link name="lower_arm">
    <visual>
      <geometry>
        <cylinder length="0.5" radius="0.05"/>
      </geometry>
      <material name="silver">
        <color rgba="0.75 0.75 0.75 1"/>
      </material>
      <origin rpy="0 0 0" xyz="0 0 0.25"/>
    </visual>
  </link>
  <joint name="elbow" type="continuous">
    <axis xyz="0 1 0"/>
    <parent link="upper_arm"/>
    <child link="lower_arm"/>
    <origin rpy="0 0 0" xyz="0.0 -0.1 0.45"/>
  </joint>

</robot>
