<?xml version="1.0"?>
<robot name="simple_myo_robot_gazebo">
  <link name ="world"/>
  <link name="base_link">
    <visual>
      <geometry>
        <cylinder length="0.05" radius="0.1"/>
      </geometry>
      <material name="silver">
        <color rgba="0.75 0.75 0.75 1"/>
      </material>
      <origin rpy="0 0 0" xyz="0 0 0"/>
    </visual>
    <collision>
      <geometry>
        <cylinder length="0.05" radius="0.1"/>
      </geometry>
      <origin rpy="0 0 0" xyz="0 0 0"/>
    </collision>
    <inertial>
      <mass value="1.0"/>
      <origin rpy="0 0 0" xyz="0 0 0"/>
      <inertia ixx="0.0027" iyy="0.0027" izz="0.005"
               ixy="0" ixz="0" iyz="0" />
    </inertial>
  </link>
  <joint name="fixed" type="fixed">
    <parent link ="world"/>
    <child link ="base_link"/>
  </joint>

  <link name="upper_arm">
    <visual>
      <geometry>
        <cylinder length="0.5" radius="0.05"/>
      </geometry>
      <material name="silver">
        <color rgba="0.75 0.75 0.75 1"/>
      </material>
      <origin rpy="0 0 0" xyz="0 0 0.25"/>
    </visual>
    <collision>
      <geometry>
        <cylinder length="0.5" radius="0.05"/>
      </geometry>
      <origin rpy="0 0 0" xyz="0 0 0.25"/>
    </collision>
    <inertial>
      <mass value="1.0"/>
      <origin rpy="0 0 0" xyz="0 0 0.25"/>
      <inertia ixx="0.02146" iyy="0.02146" izz="0.00125"
               ixy="0" ixz="0" iyz="0" />
    </inertial>
  </link>
  <joint name="shoulder" type="fixed">
    <parent link ="base_link"/>
    <child link ="upper_arm"/>
  </joint>

  <link name="lower_arm">
    <visual>
      <geometry>
        <cylinder length="0.5" radius="0.05"/>
      </geometry>
      <material name="silver">
        <color rgba="0.75 0.75 0.75 1"/>
      </material>
      <origin rpy="0 0 0" xyz="0 0 0.25"/>
    </visual>
    <collision>
      <geometry>
        <cylinder length="0.5" radius="0.05"/>
      </geometry>
      <origin rpy="0 0 0" xyz="0 0 0.25"/>
    </collision>
    <inertial>
      <mass value="1.0"/>
      <origin rpy="0 0 0" xyz="0 0 0.25"/>
      <inertia ixx="0.01396" iyy="0.01396" izz="0.00125"
               ixy="0" ixz="0" iyz="0" />
    </inertial>
  </link>
  <joint name="elbow" type="continuous">
    <axis xyz="0 1 0"/>
    <parent link="upper_arm"/>
    <child link="lower_arm"/>
    <origin rpy="0 0 0" xyz="0.0 -0.1 0.45"/>
  </joint>
  <transmission name="tran0">
    <type>transmission_interface/SimpleTransmission</type>
    <joint name="elbow">
      <hardwareInterface>PositionJointInterface</hardwareInterface>
    </joint>
    <actuator name="motor0">
      <hardwareInterface>PositionJointInterface</hardwareInterface>
      <mechanicalReduction>1</mechanicalReduction>
    </actuator>
  </transmission>
  <gazebo>
    <plugin name="control" filename="libgazebo_ros_control.so"/>
    <plugin name="roboySim" filename="libroboySim.so">
     <myoMuscle name="elbow">
      <link name="upper_arm">
       <viaPoint>0.0 0.0 0.0</viaPoint>
      </link>
      <link name="hand">
       <viaPoint>0.0 0.5 0.0</viaPoint>
      </link>
       <motor>
        <bemf_constant>0.001488</bemf_constant> <!--V/rpm-->
        <torque_constant>14.2</torque_constant> <!--mNm/A-->
        <inductance>0.118</inductance> <!--mH-->
        <resistance>0.797</resistance> <!--Ohm-->
        <inertiaMoment>4.09</inertiaMoment> <!--gcm^2-->
       </motor>
       <gear>
        <ratio>53</ratio>
        <efficiency>0.59</efficiency>
        <inertiaMoment>0.4</inertiaMoment> <!--gcm^2-->
       </gear>
       <spindle>
        <radius>0.005</radius> <!--m-->
       </spindle>
       <SEE>
        <stiffness>1.0</stiffness>
        <!-- <length>0.5</length> -->
        <length>0.1</length>
       </SEE>
      </myoMuscle>
    </plugin>
  </gazebo>


</robot>
